python3 traffic.py 
(False, "HTTPConnectionPool(host='192.168.1.150', port=4000): Max retries exceeded with url: /config?ip=192.168.1.151&testing_label=Label_Tun (Caused by NewConnectionError('<urllib3.connection.HTTPConnection object at 0x7faf7fbd4b90>: Failed to establish a new connection: [Errno 111] Connection refused'))")
(False, "HTTPConnectionPool(host='192.168.1.150', port=4000): Max retries exceeded with url: /upload (Caused by NewConnectionError('<urllib3.connection.HTTPConnection object at 0x7faf7fbce150>: Failed to establish a new connection: [Errno 111] Connection refused'))")
(False, "HTTPConnectionPool(host='192.168.1.150', port=4000): Max retries exceeded with url: /phase-one?timeout=120&permissions=False&reboot=False (Caused by NewConnectionError('<urllib3.connection.HTTPConnection object at 0x7faf7fbeea90>: Failed to establish a new connection: [Errno 111] Connection refused'))")
(False, "HTTPConnectionPool(host='192.168.1.150', port=4000): Max retries exceeded with url: /phase-two?timeout=120&monkey=True (Caused by NewConnectionError('<urllib3.connection.HTTPConnection object at 0x7faf7fbf9790>: Failed to establish a new connection: [Errno 111] Connection refused'))")
(False, "HTTPConnectionPool(host='192.168.1.150', port=4000): Max retries exceeded with url: /analysis (Caused by NewConnectionError('<urllib3.connection.HTTPConnection object at 0x7faf7fc00490>: Failed to establish a new connection: [Errno 111] Connection refused'))")
(False, "HTTPConnectionPool(host='192.168.1.150', port=4000): Max retries exceeded with url: /result (Caused by NewConnectionError('<urllib3.connection.HTTPConnection object at 0x7faf7fc0a190>: Failed to establish a new connection: [Errno 111] Connection refused'))")
HTTPConnectionPool(host='192.168.1.150', port=4000): Max retries exceeded with url: /sanitize (Caused by NewConnectionError('<urllib3.connection.HTTPConnection object at 0x7faf7fc0ae50>: Failed to establish a new connection: [Errno 111] Connection refused'))
None

